2024-09-01 13:43:46,538 INFO    StreamThr :15676 [internal.py:wandb_internal():85] W&B internal server running at pid: 15676, started at: 2024-09-01 13:43:46.538321
2024-09-01 13:43:46,540 DEBUG   HandlerThread:15676 [handler.py:handle_request():158] handle_request: status
2024-09-01 13:43:46,544 INFO    WriterThread:15676 [datastore.py:open_for_write():87] open: C:\Users\UMI\Desktop\gan\wandb\run-20240901_134346-cdlncnwz\run-cdlncnwz.wandb
2024-09-01 13:43:46,544 DEBUG   SenderThread:15676 [sender.py:send():391] send: header
2024-09-01 13:43:46,545 DEBUG   SenderThread:15676 [sender.py:send():391] send: run
2024-09-01 13:43:47,034 ERROR   SenderThread:15676 [internal_api.py:execute():349] 404 response executing GraphQL.
2024-09-01 13:43:47,034 ERROR   SenderThread:15676 [internal_api.py:execute():350] {"errors":[{"message":"entity your_wandb_entity not found during upsertBucket","path":["upsertBucket"]}],"data":{"upsertBucket":null}}
2024-09-01 13:43:47,038 ERROR   SenderThread:15676 [sender.py:send_run():1021] It appears that you do not have permission to access the requested resource. Please reach out to the project owner to grant you access. If you have the correct permissions, verify that there are no issues with your networking setup.(Error 404: Not Found)
Traceback (most recent call last):
  File "C:\Users\UMI\Desktop\myenv\Lib\site-packages\wandb\sdk\lib\retry.py", line 131, in __call__
    result = self._call_fn(*args, **kwargs)
             ^^^^^^^^^^^^^^^^^^^^^^^^^^^^^^
  File "C:\Users\UMI\Desktop\myenv\Lib\site-packages\wandb\sdk\internal\internal_api.py", line 345, in execute
    return self.client.execute(*args, **kwargs)  # type: ignore
           ^^^^^^^^^^^^^^^^^^^^^^^^^^^^^^^^^^^^
  File "C:\Users\UMI\Desktop\myenv\Lib\site-packages\wandb\vendor\gql-0.2.0\wandb_gql\client.py", line 52, in execute
    result = self._get_result(document, *args, **kwargs)
             ^^^^^^^^^^^^^^^^^^^^^^^^^^^^^^^^^^^^^^^^^^^
  File "C:\Users\UMI\Desktop\myenv\Lib\site-packages\wandb\vendor\gql-0.2.0\wandb_gql\client.py", line 60, in _get_result
    return self.transport.execute(document, *args, **kwargs)
           ^^^^^^^^^^^^^^^^^^^^^^^^^^^^^^^^^^^^^^^^^^^^^^^^^
  File "C:\Users\UMI\Desktop\myenv\Lib\site-packages\wandb\sdk\lib\gql_request.py", line 59, in execute
    request.raise_for_status()
  File "C:\Users\UMI\Desktop\myenv\Lib\site-packages\requests\models.py", line 1024, in raise_for_status
    raise HTTPError(http_error_msg, response=self)
requests.exceptions.HTTPError: 404 Client Error: Not Found for url: https://api.wandb.ai/graphql

During handling of the above exception, another exception occurred:

Traceback (most recent call last):
  File "C:\Users\UMI\Desktop\myenv\Lib\site-packages\wandb\sdk\internal\sender.py", line 1019, in send_run
    server_run = self._init_run(run, config_value_dict)
                 ^^^^^^^^^^^^^^^^^^^^^^^^^^^^^^^^^^^^^^
  File "C:\Users\UMI\Desktop\myenv\Lib\site-packages\wandb\sdk\internal\sender.py", line 1091, in _init_run
    server_run, inserted, server_messages = self._api.upsert_run(
                                            ^^^^^^^^^^^^^^^^^^^^^
  File "C:\Users\UMI\Desktop\myenv\Lib\site-packages\wandb\apis\normalize.py", line 73, in wrapper
    raise err
  File "C:\Users\UMI\Desktop\myenv\Lib\site-packages\wandb\apis\normalize.py", line 41, in wrapper
    return func(*args, **kwargs)
           ^^^^^^^^^^^^^^^^^^^^^
  File "C:\Users\UMI\Desktop\myenv\Lib\site-packages\wandb\sdk\internal\internal_api.py", line 2224, in upsert_run
    response = self.gql(
               ^^^^^^^^^
  File "C:\Users\UMI\Desktop\myenv\Lib\site-packages\wandb\sdk\internal\internal_api.py", line 317, in gql
    ret = self._retry_gql(
          ^^^^^^^^^^^^^^^^
  File "C:\Users\UMI\Desktop\myenv\Lib\site-packages\wandb\sdk\lib\retry.py", line 147, in __call__
    retry_timedelta_triggered = check_retry_fn(e)
                                ^^^^^^^^^^^^^^^^^
  File "C:\Users\UMI\Desktop\myenv\Lib\site-packages\wandb\util.py", line 968, in check_retry_fn
    return fallback_retry_fn(e)
           ^^^^^^^^^^^^^^^^^^^^
  File "C:\Users\UMI\Desktop\myenv\Lib\site-packages\wandb\util.py", line 910, in no_retry_auth
    raise CommError(
wandb.errors.CommError: It appears that you do not have permission to access the requested resource. Please reach out to the project owner to grant you access. If you have the correct permissions, verify that there are no issues with your networking setup.(Error 404: Not Found)
2024-09-01 13:43:47,463 DEBUG   HandlerThread:15676 [handler.py:handle_request():158] handle_request: shutdown
2024-09-01 13:43:47,463 INFO    HandlerThread:15676 [handler.py:finish():884] shutting down handler
2024-09-01 13:43:47,558 INFO    WriterThread:15676 [datastore.py:close():296] close: C:\Users\UMI\Desktop\gan\wandb\run-20240901_134346-cdlncnwz\run-cdlncnwz.wandb
2024-09-01 13:43:48,042 INFO    SenderThread:15676 [sender.py:finish():1631] shutting down sender
